sudo: unable to resolve host iZ2zebcjxbz8gl9a7s3maaZ
sudo: unable to resolve host iZ2zebcjxbz8gl9a7s3maaZ
Invalid HTTP_HOST header: 'www.corncat.fun:9000'. You may need to add u'www.corncat.fun' to ALLOWED_HOSTS.
[02/Dec/2017 05:33:16] "GET / HTTP/1.1" 400 59537
Performing system checks...

System check identified no issues (0 silenced).

You have 13 unapplied migration(s). Your project may not work properly until you apply the migrations for app(s): admin, auth, contenttypes, sessions.
Run 'python manage.py migrate' to apply them.
December 02, 2017 - 05:33:09
Django version 1.11.6, using settings 'corncat.settings'
Starting development server at http://0.0.0.0:9000/
Quit the server with CONTROL-C.
Performing system checks...

System check identified no issues (0 silenced).

You have 13 unapplied migration(s). Your project may not work properly until you apply the migrations for app(s): admin, auth, contenttypes, sessions.
Run 'python manage.py migrate' to apply them.
December 02, 2017 - 05:33:48
Django version 1.11.6, using settings 'corncat.settings'
Starting development server at http://0.0.0.0:9000/
Quit the server with CONTROL-C.
Performing system checks...

System check identified no issues (0 silenced).

You have 13 unapplied migration(s). Your project may not work properly until you apply the migrations for app(s): admin, auth, contenttypes, sessions.
Run 'python manage.py migrate' to apply them.
December 02, 2017 - 05:33:56
Django version 1.11.6, using settings 'corncat.settings'
Starting development server at http://0.0.0.0:9000/
Quit the server with CONTROL-C.
Performing system checks...

System check identified no issues (0 silenced).

You have 13 unapplied migration(s). Your project may not work properly until you apply the migrations for app(s): admin, auth, contenttypes, sessions.
Run 'python manage.py migrate' to apply them.
December 02, 2017 - 05:34:01
Django version 1.11.6, using settings 'corncat.settings'
Starting development server at http://0.0.0.0:9000/
Quit the server with CONTROL-C.
Unhandled exception in thread started by <function wrapper at 0x7f9a722f31b8>
Performing system checks...

Traceback (most recent call last):
  File "/usr/local/lib/python2.7/dist-packages/django/utils/autoreload.py", line 228, in wrapper
    fn(*args, **kwargs)
  File "/usr/local/lib/python2.7/dist-packages/django/core/management/commands/runserver.py", line 125, in inner_run
    self.check(display_num_errors=True)
  File "/usr/local/lib/python2.7/dist-packages/django/core/management/base.py", line 359, in check
    include_deployment_checks=include_deployment_checks,
  File "/usr/local/lib/python2.7/dist-packages/django/core/management/base.py", line 346, in _run_checks
    return checks.run_checks(**kwargs)
  File "/usr/local/lib/python2.7/dist-packages/django/core/checks/registry.py", line 81, in run_checks
    new_errors = check(app_configs=app_configs)
  File "/usr/local/lib/python2.7/dist-packages/django/core/checks/urls.py", line 16, in check_url_config
    return check_resolver(resolver)
  File "/usr/local/lib/python2.7/dist-packages/django/core/checks/urls.py", line 26, in check_resolver
    return check_method()
  File "/usr/local/lib/python2.7/dist-packages/django/urls/resolvers.py", line 254, in check
    for pattern in self.url_patterns:
  File "/usr/local/lib/python2.7/dist-packages/django/utils/functional.py", line 35, in __get__
    res = instance.__dict__[self.name] = self.func(instance)
  File "/usr/local/lib/python2.7/dist-packages/django/urls/resolvers.py", line 405, in url_patterns
    patterns = getattr(self.urlconf_module, "urlpatterns", self.urlconf_module)
  File "/usr/local/lib/python2.7/dist-packages/django/utils/functional.py", line 35, in __get__
    res = instance.__dict__[self.name] = self.func(instance)
  File "/usr/local/lib/python2.7/dist-packages/django/urls/resolvers.py", line 398, in urlconf_module
    return import_module(self.urlconf_name)
  File "/usr/lib/python2.7/importlib/__init__.py", line 37, in import_module
    __import__(name)
  File "/home/syj/corncat/corncat/urls.py", line 19, in <module>
    from greet.view import greet
ImportError: No module named view
sudo: unable to resolve host iZ2zebcjxbz8gl9a7s3maaZ
Unhandled exception in thread started by <function wrapper at 0x7f756663c1b8>
Performing system checks...

Traceback (most recent call last):
  File "/usr/local/lib/python2.7/dist-packages/django/utils/autoreload.py", line 228, in wrapper
    fn(*args, **kwargs)
  File "/usr/local/lib/python2.7/dist-packages/django/core/management/commands/runserver.py", line 125, in inner_run
    self.check(display_num_errors=True)
  File "/usr/local/lib/python2.7/dist-packages/django/core/management/base.py", line 359, in check
    include_deployment_checks=include_deployment_checks,
  File "/usr/local/lib/python2.7/dist-packages/django/core/management/base.py", line 346, in _run_checks
    return checks.run_checks(**kwargs)
  File "/usr/local/lib/python2.7/dist-packages/django/core/checks/registry.py", line 81, in run_checks
    new_errors = check(app_configs=app_configs)
  File "/usr/local/lib/python2.7/dist-packages/django/core/checks/urls.py", line 16, in check_url_config
    return check_resolver(resolver)
  File "/usr/local/lib/python2.7/dist-packages/django/core/checks/urls.py", line 26, in check_resolver
    return check_method()
  File "/usr/local/lib/python2.7/dist-packages/django/urls/resolvers.py", line 254, in check
    for pattern in self.url_patterns:
  File "/usr/local/lib/python2.7/dist-packages/django/utils/functional.py", line 35, in __get__
    res = instance.__dict__[self.name] = self.func(instance)
  File "/usr/local/lib/python2.7/dist-packages/django/urls/resolvers.py", line 405, in url_patterns
    patterns = getattr(self.urlconf_module, "urlpatterns", self.urlconf_module)
  File "/usr/local/lib/python2.7/dist-packages/django/utils/functional.py", line 35, in __get__
    res = instance.__dict__[self.name] = self.func(instance)
  File "/usr/local/lib/python2.7/dist-packages/django/urls/resolvers.py", line 398, in urlconf_module
    return import_module(self.urlconf_name)
  File "/usr/lib/python2.7/importlib/__init__.py", line 37, in import_module
    __import__(name)
  File "/home/syj/corncat/corncat/urls.py", line 19, in <module>
    from greet.view import greet
ImportError: No module named view
sudo: unable to resolve host iZ2zebcjxbz8gl9a7s3maaZ
[02/Dec/2017 05:35:03] "GET / HTTP/1.1" 200 71
[02/Dec/2017 05:42:30] "GET / HTTP/1.1" 200 71
